2024-09-17 08:16:05.584025 - ERROR: Erro ao executar a consulta: (pymysql.err.ProgrammingError) (1064, "You have an error in your SQL syntax; check the manual that corresponds to your MariaDB server version for the right syntax to use near 'desc, prestador, morador, chavePresente, eventoAt FROM chave ORDER BY qtd_con...' at line 1")
[SQL: SELECT id, nome, desc, prestador, morador, chavePresente, eventoAt FROM chave ORDER BY qtd_control_condo ASC]
(Background on this error at: https://sqlalche.me/e/14/f405)
Traceback (most recent call last):
  File "C:\ProgramData\anaconda3\Lib\site-packages\sqlalchemy\engine\base.py", line 1819, in _execute_context
    self.dialect.do_execute(
  File "C:\ProgramData\anaconda3\Lib\site-packages\sqlalchemy\engine\default.py", line 732, in do_execute
    cursor.execute(statement, parameters)
  File "C:\ProgramData\anaconda3\Lib\site-packages\pymysql\cursors.py", line 153, in execute
    result = self._query(query)
             ^^^^^^^^^^^^^^^^^^
  File "C:\ProgramData\anaconda3\Lib\site-packages\pymysql\cursors.py", line 322, in _query
    conn.query(q)
  File "C:\ProgramData\anaconda3\Lib\site-packages\pymysql\connections.py", line 563, in query
    self._affected_rows = self._read_query_result(unbuffered=unbuffered)
                          ^^^^^^^^^^^^^^^^^^^^^^^^^^^^^^^^^^^^^^^^^^^^^^
  File "C:\ProgramData\anaconda3\Lib\site-packages\pymysql\connections.py", line 825, in _read_query_result
    result.read()
  File "C:\ProgramData\anaconda3\Lib\site-packages\pymysql\connections.py", line 1199, in read
    first_packet = self.connection._read_packet()
                   ^^^^^^^^^^^^^^^^^^^^^^^^^^^^^^
  File "C:\ProgramData\anaconda3\Lib\site-packages\pymysql\connections.py", line 775, in _read_packet
    packet.raise_for_error()
  File "C:\ProgramData\anaconda3\Lib\site-packages\pymysql\protocol.py", line 219, in raise_for_error
    err.raise_mysql_exception(self._data)
  File "C:\ProgramData\anaconda3\Lib\site-packages\pymysql\err.py", line 150, in raise_mysql_exception
    raise errorclass(errno, errval)
pymysql.err.ProgrammingError: (1064, "You have an error in your SQL syntax; check the manual that corresponds to your MariaDB server version for the right syntax to use near 'desc, prestador, morador, chavePresente, eventoAt FROM chave ORDER BY qtd_con...' at line 1")

The above exception was the direct cause of the following exception:

Traceback (most recent call last):
  File "c:\Users\rodrigo.veiga_superl\Desktop\sistema-python\Projetos\system1\main.py", line 164, in run
    result = session.execute(self.query)
             ^^^^^^^^^^^^^^^^^^^^^^^^^^^
  File "C:\ProgramData\anaconda3\Lib\site-packages\sqlalchemy\orm\session.py", line 1712, in execute
    result = conn._execute_20(statement, params or {}, execution_options)
             ^^^^^^^^^^^^^^^^^^^^^^^^^^^^^^^^^^^^^^^^^^^^^^^^^^^^^^^^^^^^
  File "C:\ProgramData\anaconda3\Lib\site-packages\sqlalchemy\engine\base.py", line 1631, in _execute_20
    return meth(self, args_10style, kwargs_10style, execution_options)
           ^^^^^^^^^^^^^^^^^^^^^^^^^^^^^^^^^^^^^^^^^^^^^^^^^^^^^^^^^^^
  File "C:\ProgramData\anaconda3\Lib\site-packages\sqlalchemy\sql\elements.py", line 332, in _execute_on_connection
    return connection._execute_clauseelement(
           ^^^^^^^^^^^^^^^^^^^^^^^^^^^^^^^^^^
  File "C:\ProgramData\anaconda3\Lib\site-packages\sqlalchemy\engine\base.py", line 1498, in _execute_clauseelement
    ret = self._execute_context(
          ^^^^^^^^^^^^^^^^^^^^^^
  File "C:\ProgramData\anaconda3\Lib\site-packages\sqlalchemy\engine\base.py", line 1862, in _execute_context
    self._handle_dbapi_exception(
  File "C:\ProgramData\anaconda3\Lib\site-packages\sqlalchemy\engine\base.py", line 2043, in _handle_dbapi_exception
    util.raise_(
  File "C:\ProgramData\anaconda3\Lib\site-packages\sqlalchemy\util\compat.py", line 208, in raise_
    raise exception
  File "C:\ProgramData\anaconda3\Lib\site-packages\sqlalchemy\engine\base.py", line 1819, in _execute_context
    self.dialect.do_execute(
  File "C:\ProgramData\anaconda3\Lib\site-packages\sqlalchemy\engine\default.py", line 732, in do_execute
    cursor.execute(statement, parameters)
  File "C:\ProgramData\anaconda3\Lib\site-packages\pymysql\cursors.py", line 153, in execute
    result = self._query(query)
             ^^^^^^^^^^^^^^^^^^
  File "C:\ProgramData\anaconda3\Lib\site-packages\pymysql\cursors.py", line 322, in _query
    conn.query(q)
  File "C:\ProgramData\anaconda3\Lib\site-packages\pymysql\connections.py", line 563, in query
    self._affected_rows = self._read_query_result(unbuffered=unbuffered)
                          ^^^^^^^^^^^^^^^^^^^^^^^^^^^^^^^^^^^^^^^^^^^^^^
  File "C:\ProgramData\anaconda3\Lib\site-packages\pymysql\connections.py", line 825, in _read_query_result
    result.read()
  File "C:\ProgramData\anaconda3\Lib\site-packages\pymysql\connections.py", line 1199, in read
    first_packet = self.connection._read_packet()
                   ^^^^^^^^^^^^^^^^^^^^^^^^^^^^^^
  File "C:\ProgramData\anaconda3\Lib\site-packages\pymysql\connections.py", line 775, in _read_packet
    packet.raise_for_error()
  File "C:\ProgramData\anaconda3\Lib\site-packages\pymysql\protocol.py", line 219, in raise_for_error
    err.raise_mysql_exception(self._data)
  File "C:\ProgramData\anaconda3\Lib\site-packages\pymysql\err.py", line 150, in raise_mysql_exception
    raise errorclass(errno, errval)
sqlalchemy.exc.ProgrammingError: (pymysql.err.ProgrammingError) (1064, "You have an error in your SQL syntax; check the manual that corresponds to your MariaDB server version for the right syntax to use near 'desc, prestador, morador, chavePresente, eventoAt FROM chave ORDER BY qtd_con...' at line 1")
[SQL: SELECT id, nome, desc, prestador, morador, chavePresente, eventoAt FROM chave ORDER BY qtd_control_condo ASC]
(Background on this error at: https://sqlalche.me/e/14/f405)

2024-09-17 08:16:16.462693 - ERROR: Erro ao executar a consulta: (pymysql.err.OperationalError) (1054, "Unknown column 'qtd_control_condo' in 'order clause'")
[SQL: SELECT id, nome, person_uuid, room_webhook FROM persons ORDER BY qtd_control_condo ASC]
(Background on this error at: https://sqlalche.me/e/14/e3q8)
Traceback (most recent call last):
  File "C:\ProgramData\anaconda3\Lib\site-packages\sqlalchemy\engine\base.py", line 1819, in _execute_context
    self.dialect.do_execute(
  File "C:\ProgramData\anaconda3\Lib\site-packages\sqlalchemy\engine\default.py", line 732, in do_execute
    cursor.execute(statement, parameters)
  File "C:\ProgramData\anaconda3\Lib\site-packages\pymysql\cursors.py", line 153, in execute
    result = self._query(query)
             ^^^^^^^^^^^^^^^^^^
  File "C:\ProgramData\anaconda3\Lib\site-packages\pymysql\cursors.py", line 322, in _query
    conn.query(q)
  File "C:\ProgramData\anaconda3\Lib\site-packages\pymysql\connections.py", line 563, in query
    self._affected_rows = self._read_query_result(unbuffered=unbuffered)
                          ^^^^^^^^^^^^^^^^^^^^^^^^^^^^^^^^^^^^^^^^^^^^^^
  File "C:\ProgramData\anaconda3\Lib\site-packages\pymysql\connections.py", line 825, in _read_query_result
    result.read()
  File "C:\ProgramData\anaconda3\Lib\site-packages\pymysql\connections.py", line 1199, in read
    first_packet = self.connection._read_packet()
                   ^^^^^^^^^^^^^^^^^^^^^^^^^^^^^^
  File "C:\ProgramData\anaconda3\Lib\site-packages\pymysql\connections.py", line 775, in _read_packet
    packet.raise_for_error()
  File "C:\ProgramData\anaconda3\Lib\site-packages\pymysql\protocol.py", line 219, in raise_for_error
    err.raise_mysql_exception(self._data)
  File "C:\ProgramData\anaconda3\Lib\site-packages\pymysql\err.py", line 150, in raise_mysql_exception
    raise errorclass(errno, errval)
pymysql.err.OperationalError: (1054, "Unknown column 'qtd_control_condo' in 'order clause'")

The above exception was the direct cause of the following exception:

Traceback (most recent call last):
  File "c:\Users\rodrigo.veiga_superl\Desktop\sistema-python\Projetos\system1\main.py", line 164, in run
    result = session.execute(self.query)
             ^^^^^^^^^^^^^^^^^^^^^^^^^^^
  File "C:\ProgramData\anaconda3\Lib\site-packages\sqlalchemy\orm\session.py", line 1712, in execute
    result = conn._execute_20(statement, params or {}, execution_options)
             ^^^^^^^^^^^^^^^^^^^^^^^^^^^^^^^^^^^^^^^^^^^^^^^^^^^^^^^^^^^^
  File "C:\ProgramData\anaconda3\Lib\site-packages\sqlalchemy\engine\base.py", line 1631, in _execute_20
    return meth(self, args_10style, kwargs_10style, execution_options)
           ^^^^^^^^^^^^^^^^^^^^^^^^^^^^^^^^^^^^^^^^^^^^^^^^^^^^^^^^^^^
  File "C:\ProgramData\anaconda3\Lib\site-packages\sqlalchemy\sql\elements.py", line 332, in _execute_on_connection
    return connection._execute_clauseelement(
           ^^^^^^^^^^^^^^^^^^^^^^^^^^^^^^^^^^
  File "C:\ProgramData\anaconda3\Lib\site-packages\sqlalchemy\engine\base.py", line 1498, in _execute_clauseelement
    ret = self._execute_context(
          ^^^^^^^^^^^^^^^^^^^^^^
  File "C:\ProgramData\anaconda3\Lib\site-packages\sqlalchemy\engine\base.py", line 1862, in _execute_context
    self._handle_dbapi_exception(
  File "C:\ProgramData\anaconda3\Lib\site-packages\sqlalchemy\engine\base.py", line 2043, in _handle_dbapi_exception
    util.raise_(
  File "C:\ProgramData\anaconda3\Lib\site-packages\sqlalchemy\util\compat.py", line 208, in raise_
    raise exception
  File "C:\ProgramData\anaconda3\Lib\site-packages\sqlalchemy\engine\base.py", line 1819, in _execute_context
    self.dialect.do_execute(
  File "C:\ProgramData\anaconda3\Lib\site-packages\sqlalchemy\engine\default.py", line 732, in do_execute
    cursor.execute(statement, parameters)
  File "C:\ProgramData\anaconda3\Lib\site-packages\pymysql\cursors.py", line 153, in execute
    result = self._query(query)
             ^^^^^^^^^^^^^^^^^^
  File "C:\ProgramData\anaconda3\Lib\site-packages\pymysql\cursors.py", line 322, in _query
    conn.query(q)
  File "C:\ProgramData\anaconda3\Lib\site-packages\pymysql\connections.py", line 563, in query
    self._affected_rows = self._read_query_result(unbuffered=unbuffered)
                          ^^^^^^^^^^^^^^^^^^^^^^^^^^^^^^^^^^^^^^^^^^^^^^
  File "C:\ProgramData\anaconda3\Lib\site-packages\pymysql\connections.py", line 825, in _read_query_result
    result.read()
  File "C:\ProgramData\anaconda3\Lib\site-packages\pymysql\connections.py", line 1199, in read
    first_packet = self.connection._read_packet()
                   ^^^^^^^^^^^^^^^^^^^^^^^^^^^^^^
  File "C:\ProgramData\anaconda3\Lib\site-packages\pymysql\connections.py", line 775, in _read_packet
    packet.raise_for_error()
  File "C:\ProgramData\anaconda3\Lib\site-packages\pymysql\protocol.py", line 219, in raise_for_error
    err.raise_mysql_exception(self._data)
  File "C:\ProgramData\anaconda3\Lib\site-packages\pymysql\err.py", line 150, in raise_mysql_exception
    raise errorclass(errno, errval)
sqlalchemy.exc.OperationalError: (pymysql.err.OperationalError) (1054, "Unknown column 'qtd_control_condo' in 'order clause'")
[SQL: SELECT id, nome, person_uuid, room_webhook FROM persons ORDER BY qtd_control_condo ASC]
(Background on this error at: https://sqlalche.me/e/14/e3q8)

2024-09-17 08:16:17.284579 - ERROR: Erro ao executar a consulta: (pymysql.err.OperationalError) (1054, "Unknown column 'qtd_control_condo' in 'order clause'")
[SQL: SELECT id, nome, person_uuid, room_webhook FROM persons ORDER BY qtd_control_condo ASC]
(Background on this error at: https://sqlalche.me/e/14/e3q8)
Traceback (most recent call last):
  File "C:\ProgramData\anaconda3\Lib\site-packages\sqlalchemy\engine\base.py", line 1819, in _execute_context
    self.dialect.do_execute(
  File "C:\ProgramData\anaconda3\Lib\site-packages\sqlalchemy\engine\default.py", line 732, in do_execute
    cursor.execute(statement, parameters)
  File "C:\ProgramData\anaconda3\Lib\site-packages\pymysql\cursors.py", line 153, in execute
    result = self._query(query)
             ^^^^^^^^^^^^^^^^^^
  File "C:\ProgramData\anaconda3\Lib\site-packages\pymysql\cursors.py", line 322, in _query
    conn.query(q)
  File "C:\ProgramData\anaconda3\Lib\site-packages\pymysql\connections.py", line 563, in query
    self._affected_rows = self._read_query_result(unbuffered=unbuffered)
                          ^^^^^^^^^^^^^^^^^^^^^^^^^^^^^^^^^^^^^^^^^^^^^^
  File "C:\ProgramData\anaconda3\Lib\site-packages\pymysql\connections.py", line 825, in _read_query_result
    result.read()
  File "C:\ProgramData\anaconda3\Lib\site-packages\pymysql\connections.py", line 1199, in read
    first_packet = self.connection._read_packet()
                   ^^^^^^^^^^^^^^^^^^^^^^^^^^^^^^
  File "C:\ProgramData\anaconda3\Lib\site-packages\pymysql\connections.py", line 775, in _read_packet
    packet.raise_for_error()
  File "C:\ProgramData\anaconda3\Lib\site-packages\pymysql\protocol.py", line 219, in raise_for_error
    err.raise_mysql_exception(self._data)
  File "C:\ProgramData\anaconda3\Lib\site-packages\pymysql\err.py", line 150, in raise_mysql_exception
    raise errorclass(errno, errval)
pymysql.err.OperationalError: (1054, "Unknown column 'qtd_control_condo' in 'order clause'")

The above exception was the direct cause of the following exception:

Traceback (most recent call last):
  File "c:\Users\rodrigo.veiga_superl\Desktop\sistema-python\Projetos\system1\main.py", line 164, in run
    result = session.execute(self.query)
             ^^^^^^^^^^^^^^^^^^^^^^^^^^^
  File "C:\ProgramData\anaconda3\Lib\site-packages\sqlalchemy\orm\session.py", line 1712, in execute
    result = conn._execute_20(statement, params or {}, execution_options)
             ^^^^^^^^^^^^^^^^^^^^^^^^^^^^^^^^^^^^^^^^^^^^^^^^^^^^^^^^^^^^
  File "C:\ProgramData\anaconda3\Lib\site-packages\sqlalchemy\engine\base.py", line 1631, in _execute_20
    return meth(self, args_10style, kwargs_10style, execution_options)
           ^^^^^^^^^^^^^^^^^^^^^^^^^^^^^^^^^^^^^^^^^^^^^^^^^^^^^^^^^^^
  File "C:\ProgramData\anaconda3\Lib\site-packages\sqlalchemy\sql\elements.py", line 332, in _execute_on_connection
    return connection._execute_clauseelement(
           ^^^^^^^^^^^^^^^^^^^^^^^^^^^^^^^^^^
  File "C:\ProgramData\anaconda3\Lib\site-packages\sqlalchemy\engine\base.py", line 1498, in _execute_clauseelement
    ret = self._execute_context(
          ^^^^^^^^^^^^^^^^^^^^^^
  File "C:\ProgramData\anaconda3\Lib\site-packages\sqlalchemy\engine\base.py", line 1862, in _execute_context
    self._handle_dbapi_exception(
  File "C:\ProgramData\anaconda3\Lib\site-packages\sqlalchemy\engine\base.py", line 2043, in _handle_dbapi_exception
    util.raise_(
  File "C:\ProgramData\anaconda3\Lib\site-packages\sqlalchemy\util\compat.py", line 208, in raise_
    raise exception
  File "C:\ProgramData\anaconda3\Lib\site-packages\sqlalchemy\engine\base.py", line 1819, in _execute_context
    self.dialect.do_execute(
  File "C:\ProgramData\anaconda3\Lib\site-packages\sqlalchemy\engine\default.py", line 732, in do_execute
    cursor.execute(statement, parameters)
  File "C:\ProgramData\anaconda3\Lib\site-packages\pymysql\cursors.py", line 153, in execute
    result = self._query(query)
             ^^^^^^^^^^^^^^^^^^
  File "C:\ProgramData\anaconda3\Lib\site-packages\pymysql\cursors.py", line 322, in _query
    conn.query(q)
  File "C:\ProgramData\anaconda3\Lib\site-packages\pymysql\connections.py", line 563, in query
    self._affected_rows = self._read_query_result(unbuffered=unbuffered)
                          ^^^^^^^^^^^^^^^^^^^^^^^^^^^^^^^^^^^^^^^^^^^^^^
  File "C:\ProgramData\anaconda3\Lib\site-packages\pymysql\connections.py", line 825, in _read_query_result
    result.read()
  File "C:\ProgramData\anaconda3\Lib\site-packages\pymysql\connections.py", line 1199, in read
    first_packet = self.connection._read_packet()
                   ^^^^^^^^^^^^^^^^^^^^^^^^^^^^^^
  File "C:\ProgramData\anaconda3\Lib\site-packages\pymysql\connections.py", line 775, in _read_packet
    packet.raise_for_error()
  File "C:\ProgramData\anaconda3\Lib\site-packages\pymysql\protocol.py", line 219, in raise_for_error
    err.raise_mysql_exception(self._data)
  File "C:\ProgramData\anaconda3\Lib\site-packages\pymysql\err.py", line 150, in raise_mysql_exception
    raise errorclass(errno, errval)
sqlalchemy.exc.OperationalError: (pymysql.err.OperationalError) (1054, "Unknown column 'qtd_control_condo' in 'order clause'")
[SQL: SELECT id, nome, person_uuid, room_webhook FROM persons ORDER BY qtd_control_condo ASC]
(Background on this error at: https://sqlalche.me/e/14/e3q8)

2024-09-17 08:16:31.033194 - ERROR: Erro ao executar a consulta: (pymysql.err.OperationalError) (1054, "Unknown column 'qtd_control_condo' in 'order clause'")
[SQL: SELECT id, foto, hash FROM fotos_correspondencia ORDER BY qtd_control_condo ASC]
(Background on this error at: https://sqlalche.me/e/14/e3q8)
Traceback (most recent call last):
  File "C:\ProgramData\anaconda3\Lib\site-packages\sqlalchemy\engine\base.py", line 1819, in _execute_context
    self.dialect.do_execute(
  File "C:\ProgramData\anaconda3\Lib\site-packages\sqlalchemy\engine\default.py", line 732, in do_execute
    cursor.execute(statement, parameters)
  File "C:\ProgramData\anaconda3\Lib\site-packages\pymysql\cursors.py", line 153, in execute
    result = self._query(query)
             ^^^^^^^^^^^^^^^^^^
  File "C:\ProgramData\anaconda3\Lib\site-packages\pymysql\cursors.py", line 322, in _query
    conn.query(q)
  File "C:\ProgramData\anaconda3\Lib\site-packages\pymysql\connections.py", line 563, in query
    self._affected_rows = self._read_query_result(unbuffered=unbuffered)
                          ^^^^^^^^^^^^^^^^^^^^^^^^^^^^^^^^^^^^^^^^^^^^^^
  File "C:\ProgramData\anaconda3\Lib\site-packages\pymysql\connections.py", line 825, in _read_query_result
    result.read()
  File "C:\ProgramData\anaconda3\Lib\site-packages\pymysql\connections.py", line 1199, in read
    first_packet = self.connection._read_packet()
                   ^^^^^^^^^^^^^^^^^^^^^^^^^^^^^^
  File "C:\ProgramData\anaconda3\Lib\site-packages\pymysql\connections.py", line 775, in _read_packet
    packet.raise_for_error()
  File "C:\ProgramData\anaconda3\Lib\site-packages\pymysql\protocol.py", line 219, in raise_for_error
    err.raise_mysql_exception(self._data)
  File "C:\ProgramData\anaconda3\Lib\site-packages\pymysql\err.py", line 150, in raise_mysql_exception
    raise errorclass(errno, errval)
pymysql.err.OperationalError: (1054, "Unknown column 'qtd_control_condo' in 'order clause'")

The above exception was the direct cause of the following exception:

Traceback (most recent call last):
  File "c:\Users\rodrigo.veiga_superl\Desktop\sistema-python\Projetos\system1\main.py", line 164, in run
    result = session.execute(self.query)
             ^^^^^^^^^^^^^^^^^^^^^^^^^^^
  File "C:\ProgramData\anaconda3\Lib\site-packages\sqlalchemy\orm\session.py", line 1712, in execute
    result = conn._execute_20(statement, params or {}, execution_options)
             ^^^^^^^^^^^^^^^^^^^^^^^^^^^^^^^^^^^^^^^^^^^^^^^^^^^^^^^^^^^^
  File "C:\ProgramData\anaconda3\Lib\site-packages\sqlalchemy\engine\base.py", line 1631, in _execute_20
    return meth(self, args_10style, kwargs_10style, execution_options)
           ^^^^^^^^^^^^^^^^^^^^^^^^^^^^^^^^^^^^^^^^^^^^^^^^^^^^^^^^^^^
  File "C:\ProgramData\anaconda3\Lib\site-packages\sqlalchemy\sql\elements.py", line 332, in _execute_on_connection
    return connection._execute_clauseelement(
           ^^^^^^^^^^^^^^^^^^^^^^^^^^^^^^^^^^
  File "C:\ProgramData\anaconda3\Lib\site-packages\sqlalchemy\engine\base.py", line 1498, in _execute_clauseelement
    ret = self._execute_context(
          ^^^^^^^^^^^^^^^^^^^^^^
  File "C:\ProgramData\anaconda3\Lib\site-packages\sqlalchemy\engine\base.py", line 1862, in _execute_context
    self._handle_dbapi_exception(
  File "C:\ProgramData\anaconda3\Lib\site-packages\sqlalchemy\engine\base.py", line 2043, in _handle_dbapi_exception
    util.raise_(
  File "C:\ProgramData\anaconda3\Lib\site-packages\sqlalchemy\util\compat.py", line 208, in raise_
    raise exception
  File "C:\ProgramData\anaconda3\Lib\site-packages\sqlalchemy\engine\base.py", line 1819, in _execute_context
    self.dialect.do_execute(
  File "C:\ProgramData\anaconda3\Lib\site-packages\sqlalchemy\engine\default.py", line 732, in do_execute
    cursor.execute(statement, parameters)
  File "C:\ProgramData\anaconda3\Lib\site-packages\pymysql\cursors.py", line 153, in execute
    result = self._query(query)
             ^^^^^^^^^^^^^^^^^^
  File "C:\ProgramData\anaconda3\Lib\site-packages\pymysql\cursors.py", line 322, in _query
    conn.query(q)
  File "C:\ProgramData\anaconda3\Lib\site-packages\pymysql\connections.py", line 563, in query
    self._affected_rows = self._read_query_result(unbuffered=unbuffered)
                          ^^^^^^^^^^^^^^^^^^^^^^^^^^^^^^^^^^^^^^^^^^^^^^
  File "C:\ProgramData\anaconda3\Lib\site-packages\pymysql\connections.py", line 825, in _read_query_result
    result.read()
  File "C:\ProgramData\anaconda3\Lib\site-packages\pymysql\connections.py", line 1199, in read
    first_packet = self.connection._read_packet()
                   ^^^^^^^^^^^^^^^^^^^^^^^^^^^^^^
  File "C:\ProgramData\anaconda3\Lib\site-packages\pymysql\connections.py", line 775, in _read_packet
    packet.raise_for_error()
  File "C:\ProgramData\anaconda3\Lib\site-packages\pymysql\protocol.py", line 219, in raise_for_error
    err.raise_mysql_exception(self._data)
  File "C:\ProgramData\anaconda3\Lib\site-packages\pymysql\err.py", line 150, in raise_mysql_exception
    raise errorclass(errno, errval)
sqlalchemy.exc.OperationalError: (pymysql.err.OperationalError) (1054, "Unknown column 'qtd_control_condo' in 'order clause'")
[SQL: SELECT id, foto, hash FROM fotos_correspondencia ORDER BY qtd_control_condo ASC]
(Background on this error at: https://sqlalche.me/e/14/e3q8)

2024-09-17 09:06:59.066020 - ERROR: Erro ao selecionar o banco de dados: 'builtin_function_or_method' object has no attribute 'addWidget'
Traceback (most recent call last):
  File "c:\Users\rodrigo.veiga_superl\Desktop\sistema-python\Projetos\system1\main.py", line 354, in handle_confirm
    self.main_window = MainWindow(self.db_mapper)
                       ^^^^^^^^^^^^^^^^^^^^^^^^^^
  File "c:\Users\rodrigo.veiga_superl\Desktop\sistema-python\Projetos\system1\main.py", line 182, in __init__
    self.layout.addWidget(self.change_condo_id_button)
    ^^^^^^^^^^^^^^^^^^^^^
AttributeError: 'builtin_function_or_method' object has no attribute 'addWidget'

2024-09-17 09:08:12.159621 - ERROR: Erro ao selecionar o banco de dados: 'builtin_function_or_method' object has no attribute 'addWidget'
Traceback (most recent call last):
  File "c:\Users\rodrigo.veiga_superl\Desktop\sistema-python\Projetos\system1\main.py", line 354, in handle_confirm
    self.main_window = MainWindow(self.db_mapper)
                       ^^^^^^^^^^^^^^^^^^^^^^^^^^
  File "c:\Users\rodrigo.veiga_superl\Desktop\sistema-python\Projetos\system1\main.py", line 182, in __init__
    self.layout.addWidget(self.change_condo_id_button)
    ^^^^^^^^^^^^^^^^^^^^^
AttributeError: 'builtin_function_or_method' object has no attribute 'addWidget'

2024-09-17 09:10:36.318419 - ERROR: Erro ao selecionar o banco de dados: 'builtin_function_or_method' object has no attribute 'addWidget'
Traceback (most recent call last):
  File "c:\Users\rodrigo.veiga_superl\Desktop\sistema-python\Projetos\system1\main.py", line 354, in handle_confirm
    self.main_window = MainWindow(self.db_mapper)
                       ^^^^^^^^^^^^^^^^^^^^^^^^^^
  File "c:\Users\rodrigo.veiga_superl\Desktop\sistema-python\Projetos\system1\main.py", line 182, in __init__
    self.layout.addWidget(self.change_condo_id_button)
    ^^^^^^^^^^^^^^^^^^^^^
AttributeError: 'builtin_function_or_method' object has no attribute 'addWidget'

2024-09-17 09:31:42.797360 - ERROR: Erro ao selecionar o banco de dados: 'builtin_function_or_method' object has no attribute 'addWidget'
Traceback (most recent call last):
  File "c:\Users\rodrigo.veiga_superl\Desktop\sistema-python\Projetos\system1\main.py", line 344, in handle_confirm
    self.main_window = MainWindow(DBMapper(new_db_url))
                       ^^^^^^^^^^^^^^^^^^^^^^^^^^^^^^^^
  File "c:\Users\rodrigo.veiga_superl\Desktop\sistema-python\Projetos\system1\main.py", line 182, in __init__
    self.layout.addWidget(self.change_condo_id_button)
    ^^^^^^^^^^^^^^^^^^^^^
AttributeError: 'builtin_function_or_method' object has no attribute 'addWidget'

